[2023-02-12 02:12:48,418] {taskinstance.py:1159} INFO - Dependencies all met for <TaskInstance: dados_climaticos.extrai_dados manual__2023-02-12T05:12:41.883317+00:00 [queued]>
[2023-02-12 02:12:48,431] {taskinstance.py:1159} INFO - Dependencies all met for <TaskInstance: dados_climaticos.extrai_dados manual__2023-02-12T05:12:41.883317+00:00 [queued]>
[2023-02-12 02:12:48,431] {taskinstance.py:1356} INFO - 
--------------------------------------------------------------------------------
[2023-02-12 02:12:48,431] {taskinstance.py:1357} INFO - Starting attempt 1 of 1
[2023-02-12 02:12:48,432] {taskinstance.py:1358} INFO - 
--------------------------------------------------------------------------------
[2023-02-12 02:12:48,495] {taskinstance.py:1377} INFO - Executing <Task(PythonOperator): extrai_dados> on 2023-02-12 05:12:41.883317+00:00
[2023-02-12 02:12:48,499] {standard_task_runner.py:52} INFO - Started process 23959 to run task
[2023-02-12 02:12:48,508] {standard_task_runner.py:79} INFO - Running: ['airflow', 'tasks', 'run', 'dados_climaticos', 'extrai_dados', 'manual__2023-02-12T05:12:41.883317+00:00', '--job-id', '20', '--raw', '--subdir', 'DAGS_FOLDER/dados_climaticos.py', '--cfg-path', '/var/folders/tf/5c5cm4z11mvb4z72rkp1jvxw0000gn/T/tmpmhw2na3i', '--error-file', '/var/folders/tf/5c5cm4z11mvb4z72rkp1jvxw0000gn/T/tmptz7k2fkm']
[2023-02-12 02:12:48,510] {standard_task_runner.py:80} INFO - Job 20: Subtask extrai_dados
[2023-02-12 02:12:48,582] {task_command.py:370} INFO - Running <TaskInstance: dados_climaticos.extrai_dados manual__2023-02-12T05:12:41.883317+00:00 [running]> on host 1.0.0.127.in-addr.arpa
[2023-02-12 02:12:48,669] {taskinstance.py:1569} INFO - Exporting the following env vars:
AIRFLOW_CTX_DAG_OWNER=airflow
AIRFLOW_CTX_DAG_ID=dados_climaticos
AIRFLOW_CTX_TASK_ID=extrai_dados
AIRFLOW_CTX_EXECUTION_DATE=2023-02-12T05:12:41.883317+00:00
AIRFLOW_CTX_TRY_NUMBER=1
AIRFLOW_CTX_DAG_RUN_ID=manual__2023-02-12T05:12:41.883317+00:00
[2023-02-12 02:12:50,360] {taskinstance.py:1889} ERROR - Task failed with exception
Traceback (most recent call last):
  File "/Users/mikeiasoliveira/Documents/Projetos/etl-crypto/.env/lib/python3.10/site-packages/airflow/operators/python.py", line 171, in execute
    return_value = self.execute_callable()
  File "/Users/mikeiasoliveira/Documents/Projetos/etl-crypto/.env/lib/python3.10/site-packages/airflow/operators/python.py", line 189, in execute_callable
    return self.python_callable(*self.op_args, **self.op_kwargs)
  File "/Users/mikeiasoliveira/Documents/Projetos/etl-crypto/dags/dados_climaticos.py", line 40, in extrai_dados
    data.to_csv(file_path + 'raw_data.csv')
  File "/Users/mikeiasoliveira/Documents/Projetos/etl-crypto/.env/lib/python3.10/site-packages/pandas/util/_decorators.py", line 211, in wrapper
    return func(*args, **kwargs)
  File "/Users/mikeiasoliveira/Documents/Projetos/etl-crypto/.env/lib/python3.10/site-packages/pandas/core/generic.py", line 3720, in to_csv
    return DataFrameRenderer(formatter).to_csv(
  File "/Users/mikeiasoliveira/Documents/Projetos/etl-crypto/.env/lib/python3.10/site-packages/pandas/util/_decorators.py", line 211, in wrapper
    return func(*args, **kwargs)
  File "/Users/mikeiasoliveira/Documents/Projetos/etl-crypto/.env/lib/python3.10/site-packages/pandas/io/formats/format.py", line 1189, in to_csv
    csv_formatter.save()
  File "/Users/mikeiasoliveira/Documents/Projetos/etl-crypto/.env/lib/python3.10/site-packages/pandas/io/formats/csvs.py", line 241, in save
    with get_handle(
  File "/Users/mikeiasoliveira/Documents/Projetos/etl-crypto/.env/lib/python3.10/site-packages/pandas/io/common.py", line 734, in get_handle
    check_parent_directory(str(handle))
  File "/Users/mikeiasoliveira/Documents/Projetos/etl-crypto/.env/lib/python3.10/site-packages/pandas/io/common.py", line 597, in check_parent_directory
    raise OSError(rf"Cannot save file into a non-existent directory: '{parent}'")
OSError: Cannot save file into a non-existent directory: '/Users/mikeiasoliveira/Documents/Projetos/etl-crypto/data/semana={data_interval_end.strftime("Y%-%m-%d")}'
[2023-02-12 02:12:50,461] {taskinstance.py:1395} INFO - Marking task as FAILED. dag_id=dados_climaticos, task_id=extrai_dados, execution_date=20230212T051241, start_date=20230212T051248, end_date=20230212T051250
[2023-02-12 02:12:50,473] {standard_task_runner.py:92} ERROR - Failed to execute job 20 for task extrai_dados (Cannot save file into a non-existent directory: '/Users/mikeiasoliveira/Documents/Projetos/etl-crypto/data/semana={data_interval_end.strftime("Y%-%m-%d")}'; 23959)
[2023-02-12 02:12:50,522] {local_task_job.py:156} INFO - Task exited with return code 1
[2023-02-12 02:12:50,553] {local_task_job.py:273} INFO - 0 downstream tasks scheduled from follow-on schedule check
