[2023-02-12 02:03:45,432] {taskinstance.py:1159} INFO - Dependencies all met for <TaskInstance: dados_climaticos.extrai_dados manual__2023-02-12T05:03:11.315156+00:00 [queued]>
[2023-02-12 02:03:45,442] {taskinstance.py:1159} INFO - Dependencies all met for <TaskInstance: dados_climaticos.extrai_dados manual__2023-02-12T05:03:11.315156+00:00 [queued]>
[2023-02-12 02:03:45,442] {taskinstance.py:1356} INFO - 
--------------------------------------------------------------------------------
[2023-02-12 02:03:45,442] {taskinstance.py:1357} INFO - Starting attempt 1 of 1
[2023-02-12 02:03:45,443] {taskinstance.py:1358} INFO - 
--------------------------------------------------------------------------------
[2023-02-12 02:03:45,463] {taskinstance.py:1377} INFO - Executing <Task(PythonOperator): extrai_dados> on 2023-02-12 05:03:11.315156+00:00
[2023-02-12 02:03:45,466] {standard_task_runner.py:52} INFO - Started process 23579 to run task
[2023-02-12 02:03:45,475] {standard_task_runner.py:79} INFO - Running: ['airflow', 'tasks', 'run', 'dados_climaticos', 'extrai_dados', 'manual__2023-02-12T05:03:11.315156+00:00', '--job-id', '10', '--raw', '--subdir', 'DAGS_FOLDER/dados_climaticos.py', '--cfg-path', '/var/folders/tf/5c5cm4z11mvb4z72rkp1jvxw0000gn/T/tmpwyz_7vr8', '--error-file', '/var/folders/tf/5c5cm4z11mvb4z72rkp1jvxw0000gn/T/tmp11q8yb_3']
[2023-02-12 02:03:45,478] {standard_task_runner.py:80} INFO - Job 10: Subtask extrai_dados
[2023-02-12 02:03:45,609] {task_command.py:370} INFO - Running <TaskInstance: dados_climaticos.extrai_dados manual__2023-02-12T05:03:11.315156+00:00 [running]> on host 1.0.0.127.in-addr.arpa
[2023-02-12 02:03:45,715] {taskinstance.py:1569} INFO - Exporting the following env vars:
AIRFLOW_CTX_DAG_OWNER=airflow
AIRFLOW_CTX_DAG_ID=dados_climaticos
AIRFLOW_CTX_TASK_ID=extrai_dados
AIRFLOW_CTX_EXECUTION_DATE=2023-02-12T05:03:11.315156+00:00
AIRFLOW_CTX_TRY_NUMBER=1
AIRFLOW_CTX_DAG_RUN_ID=manual__2023-02-12T05:03:11.315156+00:00
[2023-02-12 02:03:45,716] {taskinstance.py:1889} ERROR - Task failed with exception
Traceback (most recent call last):
  File "/Users/mikeiasoliveira/Documents/Projetos/etl-crypto/.env/lib/python3.10/site-packages/airflow/operators/python.py", line 169, in execute
    self.op_kwargs = self.determine_kwargs(context)
  File "/Users/mikeiasoliveira/Documents/Projetos/etl-crypto/.env/lib/python3.10/site-packages/airflow/operators/python.py", line 180, in determine_kwargs
    return KeywordParameters.determine(self.python_callable, self.op_args, context).unpacking()
  File "/Users/mikeiasoliveira/Documents/Projetos/etl-crypto/.env/lib/python3.10/site-packages/airflow/utils/operator_helpers.py", line 160, in determine
    raise ValueError(f"The key {name!r} in args is a part of kwargs and therefore reserved.")
ValueError: The key 'data_interval_end' in args is a part of kwargs and therefore reserved.
[2023-02-12 02:03:45,767] {taskinstance.py:1395} INFO - Marking task as FAILED. dag_id=dados_climaticos, task_id=extrai_dados, execution_date=20230212T050311, start_date=20230212T050345, end_date=20230212T050345
[2023-02-12 02:03:45,780] {standard_task_runner.py:92} ERROR - Failed to execute job 10 for task extrai_dados (The key 'data_interval_end' in args is a part of kwargs and therefore reserved.; 23579)
[2023-02-12 02:03:45,794] {local_task_job.py:156} INFO - Task exited with return code 1
[2023-02-12 02:03:45,821] {local_task_job.py:273} INFO - 0 downstream tasks scheduled from follow-on schedule check
